Workbook

Sheet Assumptions
A1: Trinzo AI Hub — Financial Model Assumptions
A2: Blue cells = editable inputs. All figures in euros (€). Model covers 2026–2029.
A4: CURRENT TEAM COSTS | C4: Annual (€) | D4: AI Hub % | E4: AI Hub Cost (€) | F4: Notes
A5: Conor Flynn — salary | B5: 130000 | C5: 0.667 | D5: =B5*C5 -> 86710 | E5: 1/3 to leadership/business
A6: Conor Flynn — pension (5%) | B6: 6500 | C6: 0.667 | D6: =B6*C6 -> 4335.5
A7: Conor Flynn — VHI | B7: 1500 | C7: 0.667 | D7: =B7*C7 -> 1000.5
A8: Conor Flynn — employer PRSI | B8: 14235 | C8: 0.667 | D8: =B8*C8 -> 9494.745
A9: Ciara Griffin — salary (current) | B9: 42000 | C9: 1 | D9: =B9*C9 -> 42000 | E9: Departing in 6 weeks
A10: Ciara Griffin — pension (5%) | B10: 2100 | C10: 1 | D10: =B10*C10 -> 2100
A11: Ciara Griffin — VHI | B11: 1500 | C11: 1 | D11: =B11*C11 -> 1500
A12: Ciara Griffin — employer PRSI | B12: 4599 | C12: 1 | D12: =B12*C12 -> 4599
A13: Colm — external contractor | B13: 30000 | C13: 0.5 | D13: =B13*C13 -> 15000 | E13: 50% to AI Hub
A14: Discretionary budget | B14: 12000 | C14: 1 | D14: =B14*C14 -> 12000 | E14: Events, ad-hoc contractors
A15: TOTAL CURRENT AI HUB COST | D15: =SUM(D5:D14) -> 178739.74
A17: NEW TEAM COSTS (replacing Ciara with Coordinator) | C17: Annual (€) | D17: AI Hub % | E17: AI Hub Cost (€) | F17: Notes
A18: Coordinator — salary | B18: 55000 | C18: 1 | D18: =B18*C18 -> 55000 | E18: Midpoint €50-60k range
A19: Coordinator — pension (5%) | B19: 2750 | C19: 1 | D19: =B19*C19 -> 2750
A20: Coordinator — VHI | B20: 1500 | C20: 1 | D20: =B20*C20 -> 1500
A21: Coordinator — employer PRSI | B21: 6023 | C21: 1 | D21: =B21*C21 -> 6023 | E21: ~10.95% on salary
A22: Adeline — automation engagement | B22: 18000 | C22: 1 | D22: =B22*C22 -> 18000 | E22: One-off, Year 1 only
A23: NET INCREMENTAL COST vs CIARA (Year 1) | D23: =SUM(D18:D22)-D9-D10-D11-D12 -> 33074
A25: EI RD&I GRANT ASSUMPTIONS
A26: Total grant programme value (4 years) | B26: 2100000
A27: Grant return rate (midpoint 65%) | B27: 0.65
A28: Government returns over 4 years | B28: =B26*B27 -> 1365000
A29: Net Trinzo investment over 4 years | B29: =B26-B28 -> 735000
A30: Net Trinzo investment per year | B30: =B29/4 -> 183750
A31: R&D tax credit rate on AI project work | B31: 0.325
A34: EI GRANT CONTRACTOR BENCH (annual costs, when active)
A35: Role | B35: Day Rate (€) | C35: Days/Week | D35: Weeks/Year | E35: Annual Cost (€)
A36: AI/ML Engineer | B36: 600 | C36: 3 | D36: 46 | E36: =B36*C36*D36 -> 82800
A37: Knowledge Graph Specialist | B37: 550 | C37: 3 | D37: 46 | E37: =B37*C37*D37 -> 75900
A38: AI Integration Developer | B38: 500 | C38: 2 | D38: 46 | E38: =B38*C38*D38 -> 46000
A39: Life Science Regulatory SME | B39: 900 | C39: 1.5 | D39: 44 | E39: =B39*C39*D39 -> 59400
A40: Content & Marketing Specialist | B40: 350 | C40: 1.5 | D40: 44 | E40: =B40*C40*D40 -> 23100
A41: TOTAL CONTRACTOR BENCH (annual) | E41: =SUM(E36:E40) -> 287200
A43: REVENUE ASSUMPTIONS
A44: 2026 direct AI billings (YTD Jan-May confirmed) | B44: 30000 | E44: Source: Management accounts, May 2026
A45: 2026 full-year direct AI billings (estimate) | B45: 60000 | E45: Conservative extrapolation
A46: 2026 AI-attributable core business revenue (YTD) | B46: 1100000 | E46: Source: Contracts signed Jan-May 2026 — confirmed
...

Sheet Cost Model
A1: Trinzo AI Hub — 4-Year Cost Model (2026–2029)
A2: Blue = inputs | Black = formulas | Green = links from Assumptions sheet
B4: 2026 | C4: 2027 | D4: 2028 | E4: 2029 | F4: 4-Yr Total
A5: SCENARIO A — WITHOUT EI GRANT
A6: Conor Flynn (AI Hub portion — 2/3) | B6: =Assumptions!D5+Assumptions!D6+Assumptions!D7+Assumptions!D8 -> 101540.74 | C6: =Assumptions!D5+Assumptions!D6+Assumptions!D7+Assumptions!D8 -> 101540.74 | D6: =Assumptions!D5+Assumptions!D6+Assumptions!D7+Assumptions!D8 -> 101540.74 | E6: =Assumptions!D5+Assumptions!D6+Assumptions!D7+Assumptions!D8 -> 101540.74
A7: AI Project Delivery Coordinator (all-in) | B7: =Assumptions!D18+Assumptions!D19+Assumptions!D20+Assumptions!D21 -> 65273 | C7: =Assumptions!D18+Assumptions!D19+Assumptions!D20+Assumptions!D21 -> 65273 | D7: =Assumptions!D18+Assumptions!D19+Assumptions!D20+Assumptions!D21 -> 65273 | E7: =Assumptions!D18+Assumptions!D19+Assumptions!D20+Assumptions!D21 -> 65273
A8: Adeline — automation build (Year 1 only) | B8: =Assumptions!D22 -> 18000
A9: Colm (50% allocation) | B9: =Assumptions!D13 -> 15000 | C9: =Assumptions!D13 -> 15000 | D9: =Assumptions!D13 -> 15000 | E9: =Assumptions!D13 -> 15000
A10: Discretionary budget | B10: =Assumptions!D14 -> 12000 | C10: =Assumptions!D14 -> 12000 | D10: =Assumptions!D14 -> 12000 | E10: =Assumptions!D14 -> 12000
A11: R&D Tax Credit recovery (30-35% on qualifying work) | B11: =-(C6+C7+C8+C9+C10)*Assumptions!B49 -> -193813.74 | C11: =-(D6+D7+D8+D9+D10)*Assumptions!B49 -> -193813.74 | D11: =-(E6+E7+E8+E9+E10)*Assumptions!B49 -> -193813.74 | E11: =-(F6+F7+F8+F9+F10)*Assumptions!B49 -> 0
A12: NET COST — Scenario A (Without EI Grant) | B12: =SUM(B6:B11) -> 18000 | C12: =SUM(C6:C11) -> 0 | D12: =SUM(D6:D11) -> 0 | E12: =SUM(E6:E11) -> 193813.74 | F12: =SUM(B12:E12) -> 211813.74
A14: SCENARIO B — WITH EI GRANT
A15: Conor Flynn (AI Hub portion — 2/3) | B15: =Assumptions!D5+Assumptions!D6+Assumptions!D7+Assumptions!D8 -> 101540.74 | C15: =Assumptions!D5+Assumptions!D6+Assumptions!D7+Assumptions!D8 -> 101540.74 | D15: =Assumptions!D5+Assumptions!D6+Assumptions!D7+Assumptions!D8 -> 101540.74 | E15: =Assumptions!D5+Assumptions!D6+Assumptions!D7+Assumptions!D8 -> 101540.74
A16: AI Project Delivery Coordinator (all-in) | B16: =Assumptions!D18+Assumptions!D19+Assumptions!D20+Assumptions!D21 -> 65273 | C16: =Assumptions!D18+Assumptions!D19+Assumptions!D20+Assumptions!D21 -> 65273 | D16: =Assumptions!D18+Assumptions!D19+Assumptions!D20+Assumptions!D21 -> 65273 | E16: =Assumptions!D18+Assumptions!D19+Assumptions!D20+Assumptions!D21 -> 65273
A17: Adeline — automation build (Year 1 only) | B17: =Assumptions!D22 -> 18000
A18: Colm (50% allocation) | B18: =Assumptions!D13 -> 15000 | C18: =Assumptions!D13 -> 15000 | D18: =Assumptions!D13 -> 15000 | E18: =Assumptions!D13 -> 15000
A19: Discretionary budget | B19: =Assumptions!D14 -> 12000 | C19: =Assumptions!D14 -> 12000 | D19: =Assumptions!D14 -> 12000 | E19: =Assumptions!D14 -> 12000
A20: Contractor bench (EI-funded roles, active Yr 2 onward) | C20: =Assumptions!E41 -> 287200 | D20: =Assumptions!E41 -> 287200 | E20: =Assumptions!E41 -> 287200
A21: EI Grant returns (60-70% of grant programme spend) | C21: =-Assumptions!E41*Assumptions!B27 -> -186680 | D21: =-Assumptions!E41*Assumptions!B27 -> -186680 | E21: =-Assumptions!E41*Assumptions!B27 -> -186680
A22: R&D Tax Credit recovery (30-35% on qualifying work) | B22: =-(B15+B16+B17+B18+B19+B20)*Assumptions!B49 -> -211813.74 | C22: =-(C15+C16+C17+C18+C19+C20)*Assumptions!B49 -> -481013.74 | D22: =-(D15+D16+D17+D18+D19+D20)*Assumptions!B49 -> -481013.74 | E22: =-(E15+E16+E17+E18+E19+E20)*Assumptions!B49 -> -481013.74
A23: NET COST — Scenario B (With EI Grant) | B23: =SUM(B15:B22) -> 0 | C23: =SUM(C15:C22) -> -186680 | D23: =SUM(D15:D22) -> -186680 | E23: =SUM(E15:E22) -> -186680 | F23: =SUM(B23:E23) -> -560040

Sheet Revenue Model
A1: Trinzo AI Hub — 4-Year Revenue Model (2026–2029)
A2: Blue = management inputs | Black = formula-driven | Green = Assumptions links | Year 3-4 grow at assumption rates from Year 2 actuals
A4: Revenue Stream | B4: 2026 | C4: 2027 | D4: 2028 | E4: 2029 | F4: 4-Yr Total
A5: SCENARIO A — WITHOUT EI GRANT | Direct AI growth: 60%/yr from Year 2 (midpoint 50-70%)
A6: DIRECT AI REVENUE
A7: AI Training & Education | B7: 60000 | C7: =B7*(1+Assumptions!B48) -> 96000 | D7: =C7*(1+Assumptions!B48) -> 153600 | E7: =D7*(1+Assumptions!B48) -> 245760 | F7: =SUM(B7:E7) -> 555360
A8: POC Factory | B8: 200000 | C8: =B8*(1+Assumptions!B48) -> 320000 | D8: =C8*(1+Assumptions!B48) -> 512000 | E8: =D8*(1+Assumptions!B48) -> 819200 | F8: =SUM(B8:E8) -> 1851200
A9: Partner Implementations | B9: 150000 | C9: =B9*(1+Assumptions!B48) -> 240000 | D9: =C9*(1+Assumptions!B48) -> 384000 | E9: =D9*(1+Assumptions!B48) -> 614400 | F9: =SUM(B9:E9) -> 1388400
A10: Total Direct AI Revenue — Scenario A | B10: =B7+B8+B9 -> 410000 | C10: =C7+C8+C9 -> 656000 | D10: =D7+D8+D9 -> 1049600 | E10: =E7+E8+E9 -> 1679360 | F10: =SUM(B10:E10) -> 3794960
A11: AI-Attributable Core Business Revenue ★ | B11: =Assumptions!B47 -> 1800000 | C11: =B11*(1+Assumptions!B52) -> 2070000 | D11: =C11*(1+Assumptions!B52) -> 2380500 | E11: =D11*(1+Assumptions!B52) -> 2737575 | F11: =SUM(B11:E11) -> 8988075
A12: ★ €1.1M confirmed signed contracts Jan–May 2026 alone (Source: Management accounts, May 2026)
A13: TOTAL AI-ATTRIBUTABLE REVENUE — Scenario A | B13: =B10+B11 -> 2210000 | C13: =C10+C11 -> 2726000 | D13: =D10+D11 -> 3430100 | E13: =E10+E11 -> 4416935 | F13: =SUM(B13:E13) -> 12783035
A15: SCENARIO B — WITH EI GRANT | Growth: 100% Yr2 / 75% Yr3 / 50% Yr4
A16: DIRECT AI REVENUE
A17: AI Training & Education | B17: 60000 | C17: 120000 | D17: =C17*(1+Assumptions!B50) -> 210000 | E17: =D17*(1+Assumptions!B51) -> 315000 | F17: =SUM(B17:E17) -> 705000
A18: POC Factory | B18: 200000 | C18: 400000 | D18: =C18*(1+Assumptions!B50) -> 700000 | E18: =D18*(1+Assumptions!B51) -> 1050000 | F18: =SUM(B18:E18) -> 2350000
A19: Partner Implementations | B19: 150000 | C19: 300000 | D19: =C19*(1+Assumptions!B50) -> 525000 | E19: =D19*(1+Assumptions!B51) -> 787500 | F19: =SUM(B19:E19) -> 1762500
A20: Total Direct AI Revenue — Scenario B | B20: =B17+B18+B19 -> 410000 | C20: =C17+C18+C19 -> 820000 | D20: =D17+D18+D19 -> 1435000 | E20: =E17+E18+E19 -> 2152500 | F20: =SUM(B20:E20) -> 4817500
A21: AI-Attributable Core Business Revenue ★ | B21: =Assumptions!B47 -> 1800000 | C21: =B21*(1+Assumptions!B52) -> 2070000 | D21: =C21*(1+Assumptions!B52) -> 2380500 | E21: =D21*(1+Assumptions!B52) -> 2737575 | F21: =SUM(B21:E21) -> 8988075
A22: TOTAL AI-ATTRIBUTABLE REVENUE — Scenario B | B22: =B20+B21 -> 2210000 | C22: =C20+C21 -> 2890000 | D22: =D20+D21 -> 3815500 | E22: =E20+E21 -> 4890075 | F22: =SUM(B22:E22) -> 13805575
A24: DIRECT AI REVENUE — SCENARIO COMPARISON
A25: Stream | B25: Scenario | C25: 2026 | D25: 2027 | E25: 2028 | F25: 2029
A26: AI Training | B26: A – No EI (60%/yr) | C26: =B7 -> 60000 | D26: =C7 -> 96000 | E26: =D7 -> 153600 | F26: =E7 -> 245760
A27: AI Training | B27: B – EI Grant | C27: =B17 -> 60000 | D27: =C17 -> 120000 | E27: =D17 -> 210000 | F27: =E17 -> 315000
A28: POC Factory | B28: A – No EI (60%/yr) | C28: =B8 -> 200000 | D28: =C8 -> 320000 | E28: =D8 -> 512000 | F28: =E8 -> 819200
A29: POC Factory | B29: B – EI Grant | C29: =B18 -> 200000 | D29: =C18 -> 400000 | E29: =D18 -> 700000 | F29: =E18 -> 1050000
A30: Partner Impl. | B30: A – No EI (60%/yr) | C30: =B9 -> 150000 | D30: =C9 -> 240000 | E30: =D9 -> 384000 | F30: =E9 -> 614400
A31: Partner Impl. | B31: B – EI Grant | C31: =B19 -> 150000 | D31: =C19 -> 300000 | E31: =D19 -> 525000 | F31: =E19 -> 787500
A32: TOTAL DIRECT | B32: A – No EI | C32: =B10 -> 410000 | D32: =C10 -> 656000 | E32: =D10 -> 1049600 | F32: =E10 -> 1679360
A33: TOTAL DIRECT | B33: B – EI Grant | C33: =B20 -> 410000 | D33: =C20 -> 820000 | E33: =D20 -> 1435000 | F33: =E20 -> 2152500

Sheet ROI Dashboard
A1: Trinzo AI Hub — ROI Dashboard | Net Investment vs Revenue Return
A2: Shows net Trinzo investment after government returns, set against AI-attributable revenue. The case for leadership.
B4: 2026 | C4: 2027 | D4: 2028 | E4: 2029 | F4: 4-Yr Total
A5: CURRENT STATE BASELINE (2026 actual)
A6: Current AI Hub total cost | B6: =Assumptions!D15 -> 178739.74
A7: AI-attributable revenue (YTD confirmed, annualised) | B7: =Assumptions!B47 -> 1800000
A8: CURRENT ROI RATIO (revenue per € invested) | B8: =IFERROR(B7/B6,"-") -> 10.070508 | F8: €1.1M signed contracts vs €179k investment = already >6x
A10: SCENARIO A — WITHOUT EI GRANT
A11: Net Hub investment (after R&D tax credits) | B11: ='Cost Model'!B12 -> 18000 | C11: ='Cost Model'!C12 -> 0 | D11: ='Cost Model'!D12 -> 0 | E11: ='Cost Model'!E12 -> 193813.74 | F11: ='Cost Model'!F12 -> 211813.74
A12: Total AI-attributable revenue | B12: ='Revenue Model'!B13 -> 2210000 | C12: ='Revenue Model'!C13 -> 2726000 | D12: ='Revenue Model'!D13 -> 3430100 | E12: ='Revenue Model'!E13 -> 4416935 | F12: ='Revenue Model'!F13 -> 12783035
A13: Net value generated (Revenue − Cost) | B13: =B12-B11 -> 2192000 | C13: =C12-C11 -> 2726000 | D13: =D12-D11 -> 3430100 | E13: =E12-E11 -> 4223121.3 | F13: =SUM(B13:E13) -> 12571221
A14: ROI RATIO — Scenario A | B14: =IFERROR(B12/B11,"-") -> 122.77778 | C14: =IFERROR(C12/C11,"-") -> - | D14: =IFERROR(D12/D11,"-") -> - | E14: =IFERROR(E12/E11,"-") -> 22.789586 | F14: =IFERROR(F12/F11,"-") -> 60.350356
A16: SCENARIO B — WITH EI GRANT
A17: Net Hub investment (after grant returns + R&D credits) | B17: ='Cost Model'!B23 -> 0 | C17: ='Cost Model'!C23 -> -186680 | D17: ='Cost Model'!D23 -> -186680 | E17: ='Cost Model'!E23 -> -186680 | F17: ='Cost Model'!F23 -> -560040
A18: Total AI-attributable revenue | B18: ='Revenue Model'!B13 -> 2210000 | C18: ='Revenue Model'!C13 -> 2726000 | D18: ='Revenue Model'!D13 -> 3430100 | E18: ='Revenue Model'!E13 -> 4416935 | F18: ='Revenue Model'!F13 -> 12783035
A19: Net value generated (Revenue − Cost) | B19: =B18-B17 -> 2210000 | C19: =C18-C17 -> 2912680 | D19: =D18-D17 -> 3616780 | E19: =E18-E17 -> 4603615 | F19: =SUM(B19:E19) -> 13343075
A20: ROI RATIO — Scenario B | B20: =IFERROR(B18/B17,"-") -> - | C20: =IFERROR(C18/C17,"-") -> -14.602528 | D20: =IFERROR(D18/D17,"-") -> -18.374223 | E20: =IFERROR(E18/E17,"-") -> -23.660462 | F20: =IFERROR(F18/F17,"-") -> -22.825218
A22: KEY MESSAGES FOR LEADERSHIP
A23: 1. The AI Hub already generates >6x return on investment through AI-attributable pipeline and contracts.
A24: 2. The incremental cost of the new team model is modest — coordinator replaces Ciara at only ~€15-25k more per year.
A25: 3. The EI grant programme (€2.1M) is 60-70% government-funded — Trinzo's net investment is ~€160-210k/year.
A26: 4. R&D tax credits (30-35%) apply to all qualifying AI project work, reducing the effective cost further.
A27: 5. Without investment, the engine that generated €1.1M in contracts in 5 months loses its operational backbone.
A28: 6. With EI Grant: 4-year cumulative revenue substantially outpaces net investment with improving ROI each year.
